try {
    console.log(a)
    let a = 3
} catch (err) {
     alert('let перед использованием нужно объявить')
 }
